<robot name="vtol_robot">
    <link name="world" />
    <link name="vtol">
        <visual>
            <origin rpy="0 0 0" xyz="0 0 0"/>
            <geometry>
                <mesh filename="package://robot_description/meshes/base_link.DAE"/>
            </geometry>
        </visual>
    </link>

    <joint name="vtol_joint" type="floating">
        <parent link="world"/>
        <child link="vtol"/>
        <origin xyz="0 0 0" rpy="0 0 0" />
        <axis xyz="-0.9 0.15 0" />
    </joint>
</robot>